<?xml version="1.0" ?>
<robot name="ur3_clean">

  <link name="base_link">
    <collision>
      <geometry>
        <cylinder length="0.15" radius="0.06"/>
      </geometry>
      <origin rpy="0 0 0" xyz="0 0 0.075"/>
    </collision>
    <visual>
      <geometry>
        <cylinder length="0.15" radius="0.06"/>
      </geometry>
      <origin rpy="0 0 0" xyz="0 0 0.075"/>
      <material name="Gray"><color rgba="0.5 0.5 0.5 1"/></material>
    </visual>
  </link>

  <link name="shoulder_link">
    <collision>
      <geometry>
        <cylinder length="0.15" radius="0.06"/>
      </geometry>
      <origin rpy="0 1.57 0" xyz="0 0 0"/>
    </collision>
    <visual>
      <geometry>
        <cylinder length="0.15" radius="0.06"/>
      </geometry>
      <origin rpy="0 1.57 0" xyz="0 0 0"/>
      <material name="Blue"><color rgba="0 0 0.8 1"/></material>
    </visual>
  </link>

  <link name="upper_arm_link">
    <collision>
      <geometry>
        <cylinder length="0.24365" radius="0.05"/>
      </geometry>
      <origin rpy="0 1.5707 0" xyz="-0.1218 0 0.0"/> </collision>
    <visual>
      <geometry>
        <cylinder length="0.24365" radius="0.05"/>
      </geometry>
      <origin rpy="0 1.5707 0" xyz="-0.1218 0 0.0"/>
      <material name="Gray"/>
    </visual>
  </link>

  <link name="forearm_link">
    <collision>
      <geometry>
        <cylinder length="0.21325" radius="0.04"/>
      </geometry>
      <origin rpy="0 1.5707 0" xyz="-0.1066 0 0.0"/>
    </collision>
    <visual>
      <geometry>
        <cylinder length="0.21325" radius="0.04"/>
      </geometry>
      <origin rpy="0 1.5707 0" xyz="-0.1066 0 0.0"/>
      <material name="Blue"/>
    </visual>
  </link>

  <link name="wrist_1_link">
    <collision>
      <geometry>
        <cylinder length="0.12" radius="0.035"/>
      </geometry>
      <origin rpy="0 1.5707 0" xyz="0 0 0"/>
    </collision>
    <visual>
      <geometry>
        <cylinder length="0.12" radius="0.035"/>
      </geometry>
      <origin rpy="0 1.5707 0" xyz="0 0 0"/>
      <material name="Gray"/>
    </visual>
  </link>

  <link name="wrist_2_link">
    <collision>
      <geometry>
        <cylinder length="0.12" radius="0.035"/>
      </geometry>
      <origin rpy="0 0 0" xyz="0 0 0"/>
    </collision>
    <visual>
      <geometry>
        <cylinder length="0.12" radius="0.035"/>
      </geometry>
      <origin rpy="0 0 0" xyz="0 0 0"/>
      <material name="Blue"/>
    </visual>
  </link>

  <link name="wrist_3_link">
    <collision>
      <geometry>
        <cylinder length="0.10" radius="0.035"/>
      </geometry>
      <origin rpy="0 1.5707 0" xyz="0 0 0"/>
    </collision>
    <visual>
      <geometry>
        <cylinder length="0.10" radius="0.035"/>
      </geometry>
      <origin rpy="0 1.5707 0" xyz="0 0 0"/>
      <material name="Gray"/>
    </visual>
  </link>
  
  <link name="tool0"/> <joint name="shoulder_pan_joint" type="revolute">
    <parent link="base_link"/>
    <child link="shoulder_link"/>
    <origin rpy="0 0 0" xyz="0 0 0.1519"/>
    <axis xyz="0 0 1"/>
    <limit effort="54.0" lower="-6.28" upper="6.28" velocity="3.14"/>
  </joint>

  <joint name="shoulder_lift_joint" type="revolute">
    <parent link="shoulder_link"/>
    <child link="upper_arm_link"/>
    <origin rpy="0 1.570796327 0" xyz="0 0.1198 0"/>
    <axis xyz="0 1 0"/>
    <limit effort="54.0" lower="-6.28" upper="6.28" velocity="3.14"/>
  </joint>

  <joint name="elbow_joint" type="revolute">
    <parent link="upper_arm_link"/>
    <child link="forearm_link"/>
    <origin rpy="0 0 0" xyz="-0.24365 0 0"/>
    <axis xyz="0 1 0"/>
    <limit effort="28.0" lower="-3.14" upper="3.14" velocity="3.14"/>
  </joint>

  <joint name="wrist_1_joint" type="revolute">
    <parent link="forearm_link"/>
    <child link="wrist_1_link"/>
    <origin rpy="0 1.570796327 0" xyz="-0.21325 0 0.11235"/>
    <axis xyz="0 1 0"/>
    <limit effort="12.0" lower="-6.28" upper="6.28" velocity="6.28"/>
  </joint>

  <joint name="wrist_2_joint" type="revolute">
    <parent link="wrist_1_link"/>
    <child link="wrist_2_link"/>
    <origin rpy="0 0 0" xyz="0 -0.08535 0"/>
    <axis xyz="0 0 1"/>
    <limit effort="12.0" lower="-6.28" upper="6.28" velocity="6.28"/>
  </joint>

  <joint name="wrist_3_joint" type="revolute">
    <parent link="wrist_2_link"/>
    <child link="wrist_3_link"/>
    <origin rpy="0 0 0" xyz="0 0.0819 0"/>
    <axis xyz="0 1 0"/>
    <limit effort="12.0" lower="-6.28" upper="6.28" velocity="6.28"/>
  </joint>

  <joint name="wrist_3_link-tool0_fixed_joint" type="fixed">
    <origin rpy="-1.5707963267948966 0 0" xyz="0 0 0"/>
    <parent link="wrist_3_link"/>
    <child link="tool0"/>
  </joint>

</robot>